<?xml version='1.0' encoding='utf-8'?>
<robot name="ur5e_leap_right">
  <!-- Mounting base: 90° yaw so robot faces -X (toward table) at identity quaternion -->
  <material name="dark_blue">
    <color rgba="0.005 0.005 0.04 1.0" />
  </material>
  <link name="base">
    <inertial>
      <mass value="0.001" />
      <inertia ixx="1e-9" ixy="0" ixz="0" iyy="1e-9" iyz="0" izz="1e-9" />
    </inertial>
    <visual>
      <origin xyz="0 0 -0.01" rpy="0 0 0" />
      <geometry>
        <mesh filename="meshes/base_plate.obj" />
      </geometry>
      <material name="dark_blue" />
    </visual>
  </link>
  <joint name="base_yaw_joint" type="fixed">
    <parent link="base" />
    <child link="ur5e_base_link" />
    <origin rpy="0 0 1.5708" xyz="0 0 0" />
  </joint>
  <link name="ur5e_base_link">
    <inertial>
      <mass value="0.001" />
      <inertia ixx="1e-9" ixy="0" ixz="0" iyy="1e-9" iyz="0" izz="1e-9" />
    </inertial>
  </link>
  <link name="ur5e_link_0">
    <visual>
      <origin rpy="0 0 3.14159265359" xyz="0 0 0" />
      <geometry>
        <mesh filename="ur5e/meshes/visual/base.obj" />
      </geometry>
    </visual>
    <inertial>
      <mass value="4.0" />
      <origin rpy="0 0 0" xyz="0 0 0" />
      <inertia ixx="0.00443333156" ixy="0.0" ixz="0.0" iyy="0.00443333156" iyz="0.0" izz="0.0072" />
    </inertial>
  </link>
  <link name="ur5e_link_1">
    <visual>
      <origin rpy="0 0 3.14159265359" xyz="0 0 0" />
      <geometry>
        <mesh filename="ur5e/meshes/visual/shoulder.obj" />
      </geometry>
    </visual>
    <!-- <collision>
      <origin xyz="0 0 -0.05" rpy="0 0 0" />
      <geometry>
        <cylinder radius="0.06" length="0.12" />
      </geometry>
    </collision> -->
    <inertial>
      <mass value="3.7" />
      <origin rpy="0 0 0" xyz="0 0 0" />
      <inertia ixx="0.010267495893" ixy="0.0" ixz="0.0" iyy="0.010267495893" iyz="0.0" izz="0.00666" />
    </inertial>
  </link>
  <link name="ur5e_link_2">
    <visual>
      <origin rpy="1.57079632679 0 -1.57079632679" xyz="0 0 0.138" />
      <geometry>
        <mesh filename="ur5e/meshes/visual/upperarm.obj" />
      </geometry>
    </visual>
    <collision>
      <origin xyz="-0.212 0 0.135" rpy="0 1.5708 0" />
      <geometry>
        <cylinder radius="0.055" length="0.45" />
      </geometry>
    </collision>
    <inertial>
      <mass value="8.393" />
      <origin rpy="0 1.57079632679 0" xyz="-0.2125 0.0 0.138" />
      <inertia ixx="0.133885781862" ixy="0.0" ixz="0.0" iyy="0.133885781862" iyz="0.0" izz="0.0151074" />
    </inertial>
  </link>
  <link name="ur5e_link_3">
    <visual>
      <origin rpy="1.57079632679 0 -1.57079632679" xyz="0 0 0.007" />
      <geometry>
        <mesh filename="ur5e/meshes/visual/forearm.obj" />
      </geometry>
    </visual>
    <collision>
      <origin xyz="-0.186 0 0.006" rpy="0 1.5708 0" />
      <geometry>
        <cylinder radius="0.045" length="0.39" />
      </geometry>
    </collision>
    <inertial>
      <mass value="2.275" />
      <origin rpy="0 1.57079632679 0" xyz="-0.1961 0.0 0.007" />
      <inertia ixx="0.0312093550996" ixy="0.0" ixz="0.0" iyy="0.0312093550996" iyz="0.0" izz="0.004095" />
    </inertial>
  </link>
  <link name="ur5e_link_4">
    <visual>
      <origin rpy="1.57079632679 0 0" xyz="0 0 -0.127" />
      <geometry>
        <mesh filename="ur5e/meshes/visual/wrist1.obj" />
      </geometry>
    </visual>
    <collision>
      <origin xyz="0 0 -0.048" rpy="0 0 0" />
      <geometry>
        <cylinder radius="0.04" length="0.08" />
      </geometry>
    </collision>
    <inertial>
      <mass value="1.219" />
      <origin rpy="0 0 0" xyz="0 0 0" />
      <inertia ixx="0.00255989897604" ixy="0.0" ixz="0.0" iyy="0.00255989897604" iyz="0.0" izz="0.0021942" />
    </inertial>
  </link>
  <link name="ur5e_link_5">
    <visual>
      <origin rpy="0 0 0" xyz="0 0 -0.0997" />
      <geometry>
        <mesh filename="ur5e/meshes/visual/wrist2.obj" />
      </geometry>
    </visual>
    <collision>
      <origin xyz="0 0 -0.044" rpy="0 0 0" />
      <geometry>
        <cylinder radius="0.04" length="0.07" />
      </geometry>
    </collision>
    <inertial>
      <mass value="1.219" />
      <origin rpy="0 0 0" xyz="0 0 0" />
      <inertia ixx="0.00255989897604" ixy="0.0" ixz="0.0" iyy="0.00255989897604" iyz="0.0" izz="0.0021942" />
    </inertial>
  </link>
  <link name="ur5e_link_6">
    <visual>
      <origin rpy="1.57079632679 0 0" xyz="0 0 -0.0989" />
      <geometry>
        <mesh filename="ur5e/meshes/visual/wrist3.obj" />
      </geometry>
    </visual>
    <collision>
      <origin xyz="0 0 -0.023" rpy="0 0 0" />
      <geometry>
        <cylinder radius="0.035" length="0.04" />
      </geometry>
    </collision>
    <inertial>
      <mass value="0.1879" />
      <origin rpy="0 0 0" xyz="0.0 0.0 -0.0229" />
      <inertia ixx="9.89041005217e-05" ixy="0.0" ixz="0.0" iyy="9.89041005217e-05" iyz="0.0" izz="0.0001321171875" />
    </inertial>
  </link>
  <joint name="ur5e_base_inertia_joint" type="fixed">
    <parent link="ur5e_base_link" />
    <child link="ur5e_link_0" />
    <origin rpy="0 0 3.14159265359" xyz="0 0 0" />
  </joint>
  <joint name="ur5e_joint_1" type="revolute">
    <parent link="ur5e_link_0" />
    <child link="ur5e_link_1" />
    <origin rpy="0 0 0" xyz="0 0 0.1625" />
    <axis xyz="0 0 1" />
    <limit effort="150.0" lower="-6.28318530718" upper="6.28318530718" velocity="3.14159" />
    <dynamics damping="60.0" friction="1.0" />
  </joint>
  <joint name="ur5e_joint_2" type="revolute">
    <parent link="ur5e_link_1" />
    <child link="ur5e_link_2" />
    <origin rpy="1.570796327 0 0" xyz="0 0 0" />
    <axis xyz="0 0 1" />
    <limit effort="150.0" lower="-6.28318530718" upper="6.28318530718" velocity="3.14159" />
    <dynamics damping="60.0" friction="1.0" />
  </joint>
  <joint name="ur5e_joint_3" type="revolute">
    <parent link="ur5e_link_2" />
    <child link="ur5e_link_3" />
    <origin rpy="0 0 0" xyz="-0.425 0 0" />
    <axis xyz="0 0 1" />
    <limit effort="150.0" lower="-3.14159265359" upper="3.14159265359" velocity="3.14159" />
    <dynamics damping="35.0" friction="1.0" />
  </joint>
  <joint name="ur5e_joint_4" type="revolute">
    <parent link="ur5e_link_3" />
    <child link="ur5e_link_4" />
    <origin rpy="0 0 0" xyz="-0.3922 0 0.1333" />
    <axis xyz="0 0 1" />
    <limit effort="28.0" lower="-6.28318530718" upper="6.28318530718" velocity="3.14159" />
    <dynamics damping="20.0" friction="0.5" />
  </joint>
  <joint name="ur5e_joint_5" type="revolute">
    <parent link="ur5e_link_4" />
    <child link="ur5e_link_5" />
    <origin rpy="1.570796327 0 0" xyz="0 -0.0997 -2.0448811823e-11" />
    <axis xyz="0 0 1" />
    <limit effort="28.0" lower="-6.28318530718" upper="6.28318530718" velocity="3.14159" />
    <dynamics damping="20.0" friction="0.5" />
  </joint>
  <joint name="ur5e_joint_6" type="revolute">
    <parent link="ur5e_link_5" />
    <child link="ur5e_link_6" />
    <origin rpy="1.57079632659 3.14159265359 3.14159265359" xyz="0 0.0996 -2.04283014801e-11" />
    <axis xyz="0 0 1" />
    <limit effort="28.0" lower="-6.28318530718" upper="6.28318530718" velocity="3.14159" />
    <dynamics damping="15.0" friction="0.5" />
  </joint>
  <link name="ur5e_base_fixed_link">
    <inertial>
      <mass value="0.001" />
      <inertia ixx="1e-9" ixy="0" ixz="0" iyy="1e-9" iyz="0" izz="1e-9" />
    </inertial>
  </link>
  <joint name="ur5e_base_fixed_joint" type="fixed">
    <origin rpy="0 0 3.14159265359" xyz="0 0 0" />
    <parent link="ur5e_base_link" />
    <child link="ur5e_base_fixed_link" />
  </joint>
  <link name="ee_link">
    <inertial>
      <mass value="0.001" />
      <inertia ixx="1e-9" ixy="0" ixz="0" iyy="1e-9" iyz="0" izz="1e-9" />
    </inertial>
  </link>
  <joint name="ur5e_flange_joint" type="fixed">
    <parent link="ur5e_link_6" />
    <child link="ee_link" />
    <origin rpy="0 -1.57079632679 -1.57079632679" xyz="0 0 0" />
  </joint>
  <joint name="hand_base_joint" type="fixed">
    <parent link="ee_link" />
    <child link="palm_link" />
    <origin xyz="0.15 0.03 0.0005" rpy="0 0 0" />
  </joint>
  <link name="palm_link">
    <visual>
      <origin xyz="-0.0200 0.02575 -0.0347" rpy="0 0 0" />
      <geometry>
        <mesh filename="leap/meshes/visual/palm_lower.obj" />
      </geometry>
    </visual>
    <collision>
      <origin xyz="-0.009 0.008 -0.011" rpy="0 0 0" />
      <geometry>
        <box size="0.022 0.026 0.034" />
      </geometry>
    </collision>
    <collision>
      <origin xyz="-0.009 -0.037 -0.011" rpy="0 0 0" />
      <geometry>
        <box size="0.022 0.026 0.034" />
      </geometry>
    </collision>
    <collision>
      <origin xyz="-0.009 -0.082 -0.011" rpy="0 0 0" />
      <geometry>
        <box size="0.022 0.026 0.034" />
      </geometry>
    </collision>
    <collision>
      <origin xyz="-0.048 -0.033 -0.0115" rpy="0 0 0" />
      <geometry>
        <box size="0.024 0.116 0.046" />
      </geometry>
    </collision>
    <collision>
      <origin xyz="-0.0385 -0.035 -0.017" rpy="0 -0.75 0" />
      <geometry>
        <box size="0.02 0.12 0.03" />
      </geometry>
    </collision>
    <collision>
      <origin xyz="-0.078 -0.053 -0.0115" rpy="0 0 0" />
      <geometry>
        <box size="0.044 0.052 0.046" />
      </geometry>
    </collision>
    <inertial>
      <origin xyz="0 0 0" rpy="0 0 0" />
      <mass value="0.237" />
      <inertia ixx="0.000354094" ixy="-0.000001193" ixz="-0.000002445" iyy="0.000260915" iyz="-0.000002905" izz="0.000529257" />
    </inertial>
  </link>
  <!-- Virtual frame for palm pose tracking (adjust xyz/rpy to match Kuka+Allegro convention) -->
  <link name="palm_frame">
    <inertial>
      <mass value="0.001"/>
      <inertia ixx="1e-9" ixy="0" ixz="0" iyy="1e-9" iyz="0" izz="1e-9"/>
    </inertial>
  </link>
  <joint name="palm_frame_joint" type="fixed">
    <parent link="palm_link"/>
    <child link="palm_frame"/>
    <origin xyz="-0.04 -0.038 -0.035" rpy="3.14159 0 0"/>
  </joint>
  <link name="index_link_0">
    <visual>
      <origin xyz="0.0084 0.0077 0.01465" rpy="0 0 0" />
      <geometry>
        <mesh filename="leap/meshes/visual/mcp_joint.obj" />
      </geometry>
    </visual>
    <inertial>
      <origin xyz="0 0 0" rpy="0 0 0" />
      <mass value="0.1" />
      <inertia ixx="0.000026134" ixy="0.000006930" ixz="0.000000275" iyy="0.000017718" iyz="0.000000255" izz="0.000033543" />
    </inertial>
  </link>
  <link name="index_link_1">
    <visual>
      <origin xyz="0.0096 0.0002 0.0007" rpy="-1.57079 -1.57079 0" />
      <geometry>
        <mesh filename="leap/meshes/visual/pip.obj" />
      </geometry>
    </visual>
    <collision>
      <origin xyz="0.0075 -0.0002 -0.011" rpy="0 0 0" />
      <geometry>
        <box size="0.034 0.026 0.022" />
      </geometry>
    </collision>
    <inertial>
      <origin xyz="0 0 0" rpy="0 0 0" />
      <mass value="0.1" />
      <inertia ixx="0.000014994" ixy="0.000000038" ixz="0.000000013" iyy="0.000008944" iyz="0.000000034" izz="0.000013231" />
    </inertial>
  </link>
  <link name="index_link_2">
    <visual>
      <origin xyz="0.0211 -0.0084 0.0097" rpy="-3.1415926 0 0" />
      <geometry>
        <mesh filename="leap/meshes/visual/dip.obj" />
      </geometry>
    </visual>
    <collision>
      <origin xyz="0.0075 -0.030 0.015" rpy="0 0 0" />
      <geometry>
        <box size="0.034 0.032 0.026" />
      </geometry>
    </collision>
    <inertial>
      <origin xyz="0 0 0" rpy="0 0 0" />
      <mass value="0.1" />
      <inertia ixx="0.000014978" ixy="-0.000001641" ixz="-0.000000046" iyy="0.000015478" iyz="-0.000000062" izz="0.000018059" />
    </inertial>
  </link>
  <link name="index_link_3">
    <visual>
      <origin xyz="0.0132 -0.0061 0.0144" rpy="3.1415926 0 0" />
      <geometry>
        <mesh filename="leap/meshes/visual/fingertip_connector.obj" />
      </geometry>
    </visual>
    <visual>
      <origin xyz="-0.0095 -0.017 -0.002" rpy="-1.5708 0 0" />
      <geometry>
        <mesh filename="finger_tip.stl" />
      </geometry>
    </visual>
    <collision>
      <origin xyz="0 -0.018 0.0145" rpy="0 0 0" />
      <geometry>
        <box size="0.019 0.008 0.033" />
      </geometry>
    </collision>
    <collision>
      <origin xyz="0 -0.031 0.0145" rpy="0 0 0" />
      <geometry>
        <box size="0.019 0.018 0.019" />
      </geometry>
    </collision>
    <collision>
      <origin xyz="-0.00445 -0.050 0.0145" rpy="1.5708 0 -0.46" />
      <geometry>
        <cylinder radius="0.0075" length="0.024" />
      </geometry>
    </collision>
    <inertial>
      <origin xyz="0 0 0" rpy="0 0 0" />
      <mass value="0.06" />
      <inertia ixx="0.000012630" ixy="0.000000431" ixz="0" iyy="0.000005835" iyz="0" izz="0.000010736" />
    </inertial>
  </link>
  <joint name="index_joint_0" type="revolute">
    <origin xyz="-0.0122 0.03810 0.01450" rpy="-1.57079 0 1.57079" />
    <parent link="index_link_0" />
    <child link="index_link_1" />
    <axis xyz="0 0 -1" />
    <limit effort="0.5" velocity="8.48" lower="-0.595" upper="0.595" />
    <dynamics damping="0.1" friction="0.01" />
  </joint>
  <joint name="index_joint_1" type="revolute">
    <origin xyz="-0.0070 0.0230 -0.0187" rpy="1.57079 1.57079 0" />
    <parent link="palm_link" />
    <child link="index_link_0" />
    <axis xyz="0 0 -1" />
    <limit effort="0.5" velocity="8.48" lower="-0.314" upper="2.23" />
    <dynamics damping="0.1" friction="0.01" />
  </joint>
  <joint name="index_joint_2" type="revolute">
    <origin xyz="0.015 0.0143 -0.013" rpy="1.57079 -1.57079 0" />
    <parent link="index_link_1" />
    <child link="index_link_2" />
    <axis xyz="0 0 -1" />
    <limit effort="0.5" velocity="8.48" lower="-0.506" upper="1.885" />
    <dynamics damping="0.1" friction="0.01" />
  </joint>
  <joint name="index_joint_3" type="revolute">
    <origin xyz="0 -0.0361 0.0002" rpy="0 0 0" />
    <parent link="index_link_2" />
    <child link="index_link_3" />
    <axis xyz="0 0 -1" />
    <limit effort="0.5" velocity="8.48" lower="-0.366" upper="2.042" />
    <dynamics damping="0.1" friction="0.01" />
  </joint>
  <link name="middle_link_0">
    <visual>
      <origin xyz="0.0084 0.0077 0.01465" rpy="0 0 0" />
      <geometry>
        <mesh filename="leap/meshes/visual/mcp_joint.obj" />
      </geometry>
    </visual>
    <inertial>
      <origin xyz="0 0 0" rpy="0 0 0" />
      <mass value="0.1" />
      <inertia ixx="0.000026134" ixy="0.000006930" ixz="0.000000275" iyy="0.000017718" iyz="0.000000255" izz="0.000033543" />
    </inertial>
  </link>
  <link name="middle_link_1">
    <visual>
      <origin xyz="0.0096 0.0003 0.0007" rpy="-1.57079 -1.57079 0" />
      <geometry>
        <mesh filename="leap/meshes/visual/pip.obj" />
      </geometry>
    </visual>
    <collision>
      <origin xyz="0.0075 -0.0002 -0.011" rpy="0 0 0" />
      <geometry>
        <box size="0.034 0.026 0.022" />
      </geometry>
    </collision>
    <inertial>
      <origin xyz="0 0 0" rpy="0 0 0" />
      <mass value="0.1" />
      <inertia ixx="0.000014994" ixy="0.000000038" ixz="0.000000013" iyy="0.000008944" iyz="0.000000034" izz="0.000013231" />
    </inertial>
  </link>
  <link name="middle_link_2">
    <visual>
      <origin xyz="0.0211 -0.0084 0.0097" rpy="-3.14159 0 0" />
      <geometry>
        <mesh filename="leap/meshes/visual/dip.obj" />
      </geometry>
    </visual>
    <collision>
      <origin xyz="0.0075 -0.030 0.015" rpy="0 0 0" />
      <geometry>
        <box size="0.034 0.032 0.026" />
      </geometry>
    </collision>
    <inertial>
      <origin xyz="0 0 0" rpy="0 0 0" />
      <mass value="0.1" />
      <inertia ixx="0.000014978" ixy="-0.000001641" ixz="-0.000000046" iyy="0.000015478" iyz="-0.000000062" izz="0.000018059" />
    </inertial>
  </link>
  <link name="middle_link_3">
    <visual>
      <origin xyz="0.0132 -0.0061 0.01450" rpy="3.14159 0 0" />
      <geometry>
        <mesh filename="leap/meshes/visual/fingertip_connector.obj" />
      </geometry>
    </visual>
    <visual>
      <origin xyz="-0.0095 -0.017 -0.002" rpy="-1.5708 0 0" />
      <geometry>
        <mesh filename="finger_tip.stl" />
      </geometry>
    </visual>
    <collision>
      <origin xyz="0 -0.018 0.0145" rpy="0 0 0" />
      <geometry>
        <box size="0.019 0.008 0.033" />
      </geometry>
    </collision>
    <collision>
      <origin xyz="0 -0.031 0.0145" rpy="0 0 0" />
      <geometry>
        <box size="0.019 0.018 0.019" />
      </geometry>
    </collision>
    <collision>
      <origin xyz="-0.00445 -0.050 0.0145" rpy="1.5708 0 -0.46" />
      <geometry>
        <cylinder radius="0.0075" length="0.024" />
      </geometry>
    </collision>
    <inertial>
      <origin xyz="0 0 0" rpy="0 0 0" />
      <mass value="0.06" />
      <inertia ixx="0.000012630" ixy="0.000000431" ixz="0" iyy="0.000005835" iyz="0" izz="0.000010736" />
    </inertial>
  </link>
  <joint name="middle_joint_0" type="revolute">
    <origin xyz="-0.0122 0.0381 0.0145" rpy="-1.57079 0 1.57079" />
    <parent link="middle_link_0" />
    <child link="middle_link_1" />
    <axis xyz="0 0 -1" />
    <limit effort="0.5" velocity="8.48" lower="-0.595" upper="0.595" />
    <dynamics damping="0.1" friction="0.01" />
  </joint>
  <joint name="middle_joint_1" type="revolute">
    <origin xyz="-0.0071 -0.0224 -0.0187" rpy="1.57079 1.57079 0" />
    <parent link="palm_link" />
    <child link="middle_link_0" />
    <axis xyz="0 0 -1" />
    <limit effort="0.5" velocity="8.48" lower="-0.314" upper="2.23" />
    <dynamics damping="0.1" friction="0.01" />
  </joint>
  <joint name="middle_joint_2" type="revolute">
    <origin xyz="0.015 0.0143 -0.013" rpy="1.57079 -1.57079 0" />
    <parent link="middle_link_1" />
    <child link="middle_link_2" />
    <axis xyz="0 0 -1" />
    <limit effort="0.5" velocity="8.48" lower="-0.506" upper="1.885" />
    <dynamics damping="0.1" friction="0.01" />
  </joint>
  <joint name="middle_joint_3" type="revolute">
    <origin xyz="0 -0.0361 0.0002" rpy="0 0 0" />
    <parent link="middle_link_2" />
    <child link="middle_link_3" />
    <axis xyz="0 0 -1" />
    <limit effort="0.5" velocity="8.48" lower="-0.366" upper="2.042" />
    <dynamics damping="0.1" friction="0.01" />
  </joint>
  <link name="ring_link_0">
    <visual>
      <origin xyz="0.0084 0.0077 0.01465" rpy="0 0 0" />
      <geometry>
        <mesh filename="leap/meshes/visual/mcp_joint.obj" />
      </geometry>
    </visual>
    <inertial>
      <origin xyz="0 0 0" rpy="0 0 0" />
      <mass value="0.1" />
      <inertia ixx="0.000026134" ixy="0.000006930" ixz="0.000000275" iyy="0.000017718" iyz="0.000000255" izz="0.000033543" />
    </inertial>
  </link>
  <link name="ring_link_1">
    <visual>
      <origin xyz="0.0096 0.0003 0.0007" rpy="-1.57079 -1.57079 0" />
      <geometry>
        <mesh filename="leap/meshes/visual/pip.obj" />
      </geometry>
    </visual>
    <collision>
      <origin xyz="0.0075 -0.0002 -0.011" rpy="0 0 0" />
      <geometry>
        <box size="0.034 0.026 0.022" />
      </geometry>
    </collision>
    <inertial>
      <origin xyz="0 0 0" rpy="0 0 0" />
      <mass value="0.1" />
      <inertia ixx="0.000014994" ixy="0.000000038" ixz="0.000000013" iyy="0.000008944" iyz="0.000000034" izz="0.000013231" />
    </inertial>
  </link>
  <link name="ring_link_2">
    <visual>
      <origin xyz="0.0211 -0.0084 0.0097" rpy="-3.14159 0 0" />
      <geometry>
        <mesh filename="leap/meshes/visual/dip.obj" />
      </geometry>
    </visual>
    <collision>
      <origin xyz="0.0075 -0.030 0.015" rpy="0 0 0" />
      <geometry>
        <box size="0.034 0.032 0.026" />
      </geometry>
    </collision>
    <inertial>
      <origin xyz="0 0 0" rpy="0 0 0" />
      <mass value="0.1" />
      <inertia ixx="0.000014978" ixy="-0.000001641" ixz="-0.000000046" iyy="0.000015478" iyz="-0.000000062" izz="0.000018059" />
    </inertial>
  </link>
  <link name="ring_link_3">
    <visual>
      <origin xyz="0.0132 -0.0061 0.0145" rpy="3.14159 0 0" />
      <geometry>
        <mesh filename="leap/meshes/visual/fingertip_connector.obj" />
      </geometry>
    </visual>
    <visual>
      <origin xyz="-0.0095 -0.017 -0.002" rpy="-1.5708 0 0" />
      <geometry>
        <mesh filename="finger_tip.stl" />
      </geometry>
    </visual>
    <collision>
      <origin xyz="0 -0.018 0.0145" rpy="0 0 0" />
      <geometry>
        <box size="0.019 0.008 0.033" />
      </geometry>
    </collision>
    <collision>
      <origin xyz="0 -0.031 0.0145" rpy="0 0 0" />
      <geometry>
        <box size="0.019 0.018 0.019" />
      </geometry>
    </collision>
    <collision>
      <origin xyz="-0.00445 -0.050 0.0145" rpy="1.5708 0 -0.46" />
      <geometry>
        <cylinder radius="0.0075" length="0.024" />
      </geometry>
    </collision>
    <inertial>
      <origin xyz="0 0 0" rpy="0 0 0" />
      <mass value="0.06" />
      <inertia ixx="0.000012630" ixy="0.000000431" ixz="0" iyy="0.000005835" iyz="0" izz="0.000010736" />
    </inertial>
  </link>
  <joint name="ring_joint_0" type="revolute">
    <origin xyz="-0.0122 0.0381 0.0145" rpy="-1.57079 0 1.57079" />
    <parent link="ring_link_0" />
    <child link="ring_link_1" />
    <axis xyz="0 0 -1" />
    <limit effort="0.5" velocity="8.48" lower="-0.595" upper="0.595" />
    <dynamics damping="0.1" friction="0.01" />
  </joint>
  <joint name="ring_joint_1" type="revolute">
    <origin xyz="-0.00709 -0.0678 -0.0187" rpy="1.57079 1.57079 0" />
    <parent link="palm_link" />
    <child link="ring_link_0" />
    <axis xyz="0 0 -1" />
    <limit effort="0.5" velocity="8.48" lower="-0.314" upper="2.23" />
    <dynamics damping="0.1" friction="0.01" />
  </joint>
  <joint name="ring_joint_2" type="revolute">
    <origin xyz="0.015 0.0143 -0.013" rpy="1.57079 -1.57079 0" />
    <parent link="ring_link_1" />
    <child link="ring_link_2" />
    <axis xyz="0 0 -1" />
    <limit effort="0.5" velocity="8.48" lower="-0.506" upper="1.885" />
    <dynamics damping="0.1" friction="0.01" />
  </joint>
  <joint name="ring_joint_3" type="revolute">
    <origin xyz="0 -0.03609 0.0002" rpy="0 0 0" />
    <parent link="ring_link_2" />
    <child link="ring_link_3" />
    <axis xyz="0 0 -1" />
    <limit effort="0.5" velocity="8.48" lower="-0.366" upper="2.042" />
    <dynamics damping="0.1" friction="0.01" />
  </joint>
  <link name="thumb_link_0">
    <visual>
      <origin xyz="-0.0053 0.0003 0.00078" rpy="-1.57079 -1.57079 0" />
      <geometry>
        <mesh filename="leap/meshes/visual/pip.obj" />
      </geometry>
    </visual>
    <inertial>
      <origin xyz="0 0 0" rpy="0 0 0" />
      <mass value="0.1" />
      <inertia ixx="0.000014994" ixy="0.000000038" ixz="0.000000013" iyy="0.000008944" iyz="0.000000034" izz="0.000013231" />
    </inertial>
  </link>
  <link name="thumb_link_1">
    <visual>
      <origin xyz="0.01196 0 -0.0158" rpy="1.57079 0 0" />
      <geometry>
        <mesh filename="leap/meshes/visual/thumb_pip.obj" />
      </geometry>
    </visual>
    <inertial>
      <origin xyz="0 0 0" rpy="0 0 0" />
      <mass value="0.1" />
      <inertia ixx="0.000019767" ixy="0" ixz="0" iyy="0.000018300" iyz="0" izz="0.000007467" />
    </inertial>
  </link>
  <link name="thumb_link_2">
    <visual>
      <origin xyz="0.0439 0.0579 -0.0086" rpy="0 0 0" />
      <geometry>
        <mesh filename="leap/meshes/visual/thumb_dip.obj" />
      </geometry>
    </visual>
    <collision>
      <origin xyz="0 0.0105 -0.014" rpy="0 0 0" />
      <geometry>
        <box size="0.02 0.04 0.024" />
      </geometry>
    </collision>
    <inertial>
      <origin xyz="0 0 0" rpy="0 0 0" />
      <mass value="0.1" />
      <inertia ixx="0.000022300" ixy="0.000000634" ixz="0.000000068" iyy="0.000010108" iyz="0.000000066" izz="0.000020208" />
    </inertial>
  </link>
  <link name="thumb_link_3">
    <visual>
      <origin xyz="0.0625 0.0784 0.0489" rpy="0 0 0" />
      <geometry>
        <mesh filename="leap/meshes/visual/thumb_fingertip_connector.obj" />
      </geometry>
    </visual>
    <visual>
      <origin xyz="-0.0095 -0.0295 -0.0305" rpy="-1.5708 0 0" />
      <geometry>
        <mesh filename="finger_tip.stl" />
      </geometry>
    </visual>
    <collision>
      <origin xyz="0 -0.0305 -0.014" rpy="0 0 0" />
      <geometry>
        <box size="0.019 0.008 0.033" />
      </geometry>
    </collision>
    <collision>
      <origin xyz="0 -0.0435 -0.014" rpy="0 0 0" />
      <geometry>
        <box size="0.019 0.018 0.019" />
      </geometry>
    </collision>
    <collision>
      <origin xyz="-0.00445 -0.0625 -0.014" rpy="1.5708 0 -0.46" />
      <geometry>
        <cylinder radius="0.0075" length="0.024" />
      </geometry>
    </collision>
    <collision>
      <origin xyz="0 -0.0085 -0.015" rpy="0 0 0" />
      <geometry>
        <box size="0.02 0.036 0.024" />
      </geometry>
    </collision>
    <inertial>
      <origin xyz="0 0 0" rpy="0 0 0" />
      <mass value="0.1" />
      <inertia ixx="0.000041576" ixy="-0.000000998" ixz="-0.000000061" iyy="0.000008849" iyz="-0.000000198" izz="0.000040500" />
    </inertial>
  </link>
  <joint name="thumb_joint_0" type="revolute">
    <origin xyz="-0.0693 -0.0012 -0.0216" rpy="0 1.57079 0" />
    <parent link="palm_link" />
    <child link="thumb_link_0" />
    <axis xyz="0 0 -1" />
    <limit effort="0.5" velocity="8.48" lower="-0.349" upper="2.094" />
    <dynamics damping="0.1" friction="0.01" />
  </joint>
  <joint name="thumb_joint_1" type="revolute">
    <origin xyz="0 0.0143 -0.013" rpy="1.57079 -1.57079 0" />
    <parent link="thumb_link_0" />
    <child link="thumb_link_1" />
    <axis xyz="0 0 -1" />
    <limit effort="0.5" velocity="8.48" lower="-0.47" upper="2.443" />
    <dynamics damping="0.1" friction="0.01" />
  </joint>
  <joint name="thumb_joint_2" type="revolute">
    <origin xyz="0 0.0145 -0.017" rpy="-1.57079 0 0" />
    <parent link="thumb_link_1" />
    <child link="thumb_link_2" />
    <axis xyz="0 0 -1" />
    <limit effort="0.5" velocity="8.48" lower="-1.20" upper="1.90" />
    <dynamics damping="0.1" friction="0.01" />
  </joint>
  <joint name="thumb_joint_3" type="revolute">
    <origin xyz="0 0.0466 0.0002" rpy="0 0 3.14159" />
    <parent link="thumb_link_2" />
    <child link="thumb_link_3" />
    <axis xyz="0 0 -1" />
    <limit effort="0.5" velocity="8.48" lower="-1.34" upper="1.88" />
    <dynamics damping="0.1" friction="0.01" />
  </joint>
  <link name="thumb_tip">
    <inertial>
      <mass value="0.001" />
      <inertia ixx="1e-9" ixy="0" ixz="0" iyy="1e-9" iyz="0" izz="1e-9" />
    </inertial>
  </link>
  <link name="index_tip">
    <inertial>
      <mass value="0.001" />
      <inertia ixx="1e-9" ixy="0" ixz="0" iyy="1e-9" iyz="0" izz="1e-9" />
    </inertial>
  </link>
  <link name="middle_tip">
    <inertial>
      <mass value="0.001" />
      <inertia ixx="1e-9" ixy="0" ixz="0" iyy="1e-9" iyz="0" izz="1e-9" />
    </inertial>
  </link>
  <link name="ring_tip">
    <inertial>
      <mass value="0.001" />
      <inertia ixx="1e-9" ixy="0" ixz="0" iyy="1e-9" iyz="0" izz="1e-9" />
    </inertial>
  </link>
  <joint name="thumb_tip_joint" type="fixed">
    <parent link="thumb_link_3" />
    <child link="thumb_tip" />
    <origin rpy="0 0 0" xyz="0 -0.06 -0.015" />
  </joint>
  <joint name="index_tip_joint" type="fixed">
    <parent link="index_link_3" />
    <child link="index_tip" />
    <origin rpy="0 0 0" xyz="0 -0.048 0.015" />
  </joint>
  <joint name="middle_tip_joint" type="fixed">
    <parent link="middle_link_3" />
    <child link="middle_tip" />
    <origin rpy="0 0 0" xyz="0 -0.048 0.015" />
  </joint>
  <joint name="ring_tip_joint" type="fixed">
    <parent link="ring_link_3" />
    <child link="ring_tip" />
    <origin rpy="0 0 0" xyz="0 -0.048 0.015" />
  </joint>
  <link name="wrist_mount_link">
    <visual>
      <origin xyz="0.0 0 0" rpy="0 0 0" />
      <geometry>
        <mesh filename="wrist_mount.obj" />
      </geometry>
      <material name="mount_black">
        <color rgba="0.0 0.0 0.0 1.0" />
      </material>
    </visual>
    <inertial>
      <mass value="0.08" />
      <origin xyz="0 0 0" rpy="0 0 0" />
      <inertia ixx="0.00002" ixy="0.0" ixz="0.0" iyy="0.00002" iyz="0.0" izz="0.00002" />
    </inertial>
  </link>
  <joint name="wrist_mount_joint" type="fixed">
    <parent link="ur5e_link_6" />
    <child link="wrist_mount_link" />
    <origin xyz="0.0 0.0005 0" rpy="1.57079632679 0 0" />
  </joint>
  <link name="camera_mount_link">
    <visual>
      <origin xyz="0 0 0" rpy="0 0 0" />
      <geometry>
        <mesh filename="camera_mount.obj" />
      </geometry>
      <material name="mount_black2">
        <color rgba="0.0 0.0 0.0 1.0" />
      </material>
    </visual>
    <inertial>
      <mass value="0.04" />
      <origin xyz="0 0 0" rpy="0 0 0" />
      <inertia ixx="0.00001" ixy="0.0" ixz="0.0" iyy="0.00001" iyz="0.0" izz="0.00001" />
    </inertial>
  </link>
  <joint name="camera_mount_joint" type="fixed">
    <parent link="wrist_mount_link" />
    <child link="camera_mount_link" />
    <origin xyz="0 0 0" rpy="0 0 0" />
  </joint>
  <link name="gemini_305_link">
    <visual>
      <origin xyz="0 0 0" rpy="3.14159 0 0" />
      <geometry>
        <mesh filename="gemini_305/meshes/gemini_305_rotated.obj" scale="0.001 0.001 0.001" />
      </geometry>
      <material name="gemini_305_gray">
        <color rgba="0.45 0.45 0.45 1" />
      </material>
    </visual>
    <collision>
      <origin xyz="0 0 0" rpy="0 0 0" />
      <geometry>
        <box size="0.042 0.042 0.025" />
      </geometry>
    </collision>
    <inertial>
      <mass value="0.065" />
      <origin xyz="0 0 0" rpy="0 0 0" />
      <inertia ixx="0.00001" ixy="0.0" ixz="0.0" iyy="0.00001" iyz="0.0" izz="0.00001" />
    </inertial>
  </link>
  <joint name="gemini_305_mount_joint" type="fixed">
    <parent link="ur5e_link_6" />
    <child link="gemini_305_link" />
    <origin xyz="0 -0.0705 -0.04" rpy="0 0 0" />
  </joint>
  <link name="gemini_305_left_camera_frame">
    <inertial>
      <mass value="0.001" />
      <inertia ixx="1e-9" ixy="0" ixz="0" iyy="1e-9" iyz="0" izz="1e-9" />
    </inertial>
  </link>
  <joint name="gemini_305_left_camera_joint" type="fixed">
    <parent link="gemini_305_link" />
    <child link="gemini_305_left_camera_frame" />
    <origin xyz="0.009 0 0.0126" rpy="0 0 0" />
  </joint>
  <link name="gemini_305_left_camera_optical_frame">
    <inertial>
      <mass value="0.001" />
      <inertia ixx="1e-9" ixy="0" ixz="0" iyy="1e-9" iyz="0" izz="1e-9" />
    </inertial>
  </link>
  <joint name="gemini_305_left_optical_joint" type="fixed">
    <parent link="gemini_305_left_camera_frame" />
    <child link="gemini_305_left_camera_optical_frame" />
    <!-- Camera looks along parent +Z; Rz(π) maps: opt +X=-parent_X (right), +Y=-parent_Y (down), +Z=+parent_Z (forward) -->
    <origin xyz="0 0 0" rpy="0 0 3.14159265" />
  </joint>
  <link name="gemini_305_right_camera_frame">
    <inertial>
      <mass value="0.001" />
      <inertia ixx="1e-9" ixy="0" ixz="0" iyy="1e-9" iyz="0" izz="1e-9" />
    </inertial>
  </link>
  <joint name="gemini_305_right_camera_joint" type="fixed">
    <parent link="gemini_305_link" />
    <child link="gemini_305_right_camera_frame" />
    <origin xyz="-0.009 0 0.0126" rpy="0 0 0" />
  </joint>
  <link name="gemini_305_right_camera_optical_frame">
    <inertial>
      <mass value="0.001" />
      <inertia ixx="1e-9" ixy="0" ixz="0" iyy="1e-9" iyz="0" izz="1e-9" />
    </inertial>
  </link>
  <joint name="gemini_305_right_optical_joint" type="fixed">
    <parent link="gemini_305_right_camera_frame" />
    <child link="gemini_305_right_camera_optical_frame" />
    <!-- Camera looks along parent +Z; Rz(π) maps: opt +X=-parent_X (right), +Y=-parent_Y (down), +Z=+parent_Z (forward) -->
    <origin xyz="0 0 0" rpy="0 0 3.14159265" />
  </joint>
</robot>