<?xml version='1.0' encoding='utf-8'?>
<robot name="ur5e_gemini_wsg50">
  <!--UR5e + WSG50 + Gemini 305. WSG50 source: caelan/pybullet-planning models/drake/wsg_50_description.-->
  <material name="dark_blue">
    <color rgba="0.005 0.005 0.04 1.0" />
  </material>
  <material name="wsg_gray">
    <color rgba="0.5 0.5 0.5 1" />
  </material>
  <material name="wsg_black">
    <color rgba="0.02 0.02 0.02 1" />
  </material>
  <material name="mount_black">
    <color rgba="0 0 0 1" />
  </material>
  <material name="fin_mount_white">
    <color rgba="1 1 1 1" />
  </material>
  <material name="soft_finger_black">
    <color rgba="0 0 0 1" />
  </material>
  <material name="gemini_305_gray">
    <color rgba="0.45 0.45 0.45 1" />
  </material>
  <link name="base">
    <inertial>
      <mass value="0.001" />
      <inertia ixx="1e-9" ixy="0" ixz="0" iyy="1e-9" iyz="0" izz="1e-9" />
    </inertial>
    <visual>
      <origin xyz="0 0 -0.01" rpy="0 0 0" />
      <geometry>
        <mesh filename="meshes/base_plate.obj" />
      </geometry>
      <material name="dark_blue" />
    </visual>
  </link>
  <link name="ur5e_base_link">
    <inertial>
      <mass value="0.001" />
      <inertia ixx="1e-9" ixy="0" ixz="0" iyy="1e-9" iyz="0" izz="1e-9" />
    </inertial>
  </link>
  <link name="ur5e_link_0">
    <visual>
      <origin rpy="0 0 3.14159265359" xyz="0 0 0" />
      <geometry>
        <mesh filename="ur5e/meshes/visual/base.obj" />
      </geometry>
    </visual>
    <inertial>
      <mass value="4.0" />
      <origin rpy="0 0 0" xyz="0 0 0" />
      <inertia ixx="0.00443333156" ixy="0.0" ixz="0.0" iyy="0.00443333156" iyz="0.0" izz="0.0072" />
    </inertial>
  </link>
  <link name="ur5e_link_1">
    <visual>
      <origin rpy="0 0 3.14159265359" xyz="0 0 0" />
      <geometry>
        <mesh filename="ur5e/meshes/visual/shoulder.obj" />
      </geometry>
    </visual>
    <inertial>
      <mass value="3.7" />
      <origin rpy="0 0 0" xyz="0 0 0" />
      <inertia ixx="0.010267495893" ixy="0.0" ixz="0.0" iyy="0.010267495893" iyz="0.0" izz="0.00666" />
    </inertial>
  </link>
  <link name="ur5e_link_2">
    <visual>
      <origin rpy="1.57079632679 0 -1.57079632679" xyz="0 0 0.138" />
      <geometry>
        <mesh filename="ur5e/meshes/visual/upperarm.obj" />
      </geometry>
    </visual>
    <collision>
      <origin xyz="-0.212 0 0.135" rpy="0 1.5708 0" />
      <geometry>
        <cylinder radius="0.055" length="0.45" />
      </geometry>
    </collision>
    <inertial>
      <mass value="8.393" />
      <origin rpy="0 1.57079632679 0" xyz="-0.2125 0.0 0.138" />
      <inertia ixx="0.133885781862" ixy="0.0" ixz="0.0" iyy="0.133885781862" iyz="0.0" izz="0.0151074" />
    </inertial>
  </link>
  <link name="ur5e_link_3">
    <visual>
      <origin rpy="1.57079632679 0 -1.57079632679" xyz="0 0 0.007" />
      <geometry>
        <mesh filename="ur5e/meshes/visual/forearm.obj" />
      </geometry>
    </visual>
    <collision>
      <origin xyz="-0.186 0 0.006" rpy="0 1.5708 0" />
      <geometry>
        <cylinder radius="0.045" length="0.39" />
      </geometry>
    </collision>
    <inertial>
      <mass value="2.275" />
      <origin rpy="0 1.57079632679 0" xyz="-0.1961 0.0 0.007" />
      <inertia ixx="0.0312093550996" ixy="0.0" ixz="0.0" iyy="0.0312093550996" iyz="0.0" izz="0.004095" />
    </inertial>
  </link>
  <link name="ur5e_link_4">
    <visual>
      <origin rpy="1.57079632679 0 0" xyz="0 0 -0.127" />
      <geometry>
        <mesh filename="ur5e/meshes/visual/wrist1.obj" />
      </geometry>
    </visual>
    <collision>
      <origin xyz="0 0 -0.048" rpy="0 0 0" />
      <geometry>
        <cylinder radius="0.04" length="0.08" />
      </geometry>
    </collision>
    <inertial>
      <mass value="1.219" />
      <origin rpy="0 0 0" xyz="0 0 0" />
      <inertia ixx="0.00255989897604" ixy="0.0" ixz="0.0" iyy="0.00255989897604" iyz="0.0" izz="0.0021942" />
    </inertial>
  </link>
  <link name="ur5e_link_5">
    <visual>
      <origin rpy="0 0 0" xyz="0 0 -0.0997" />
      <geometry>
        <mesh filename="ur5e/meshes/visual/wrist2.obj" />
      </geometry>
    </visual>
    <collision>
      <origin xyz="0 0 -0.044" rpy="0 0 0" />
      <geometry>
        <cylinder radius="0.04" length="0.07" />
      </geometry>
    </collision>
    <inertial>
      <mass value="1.219" />
      <origin rpy="0 0 0" xyz="0 0 0" />
      <inertia ixx="0.00255989897604" ixy="0.0" ixz="0.0" iyy="0.00255989897604" iyz="0.0" izz="0.0021942" />
    </inertial>
  </link>
  <link name="ur5e_link_6">
    <visual>
      <origin rpy="1.57079632679 0 0" xyz="0 0 -0.0989" />
      <geometry>
        <mesh filename="ur5e/meshes/visual/wrist3.obj" />
      </geometry>
    </visual>
    <collision>
      <origin xyz="0 0 -0.023" rpy="0 0 0" />
      <geometry>
        <cylinder radius="0.035" length="0.04" />
      </geometry>
    </collision>
    <inertial>
      <mass value="0.1879" />
      <origin rpy="0 0 0" xyz="0.0 0.0 -0.0229" />
      <inertia ixx="9.89041005217e-05" ixy="0.0" ixz="0.0" iyy="9.89041005217e-05" iyz="0.0" izz="0.0001321171875" />
    </inertial>
  </link>
  <link name="ur5e_base_fixed_link">
    <inertial>
      <mass value="0.001" />
      <inertia ixx="1e-9" ixy="0" ixz="0" iyy="1e-9" iyz="0" izz="1e-9" />
    </inertial>
  </link>
  <link name="ee_link">
    <inertial>
      <mass value="0.001" />
      <inertia ixx="1e-9" ixy="0" ixz="0" iyy="1e-9" iyz="0" izz="1e-9" />
    </inertial>
  </link>
  <joint name="base_yaw_joint" type="fixed">
    <parent link="base" />
    <child link="ur5e_base_link" />
    <origin rpy="0 0 1.5708" xyz="0 0 0" />
  </joint>
  <joint name="ur5e_base_inertia_joint" type="fixed">
    <parent link="ur5e_base_link" />
    <child link="ur5e_link_0" />
    <origin rpy="0 0 3.14159265359" xyz="0 0 0" />
  </joint>
  <joint name="ur5e_joint_1" type="revolute">
    <parent link="ur5e_link_0" />
    <child link="ur5e_link_1" />
    <origin rpy="0 0 0" xyz="0 0 0.1625" />
    <axis xyz="0 0 1" />
    <limit effort="150.0" lower="-6.28318530718" upper="6.28318530718" velocity="3.14159" />
    <dynamics damping="60.0" friction="1.0" />
  </joint>
  <joint name="ur5e_joint_2" type="revolute">
    <parent link="ur5e_link_1" />
    <child link="ur5e_link_2" />
    <origin rpy="1.570796327 0 0" xyz="0 0 0" />
    <axis xyz="0 0 1" />
    <limit effort="150.0" lower="-6.28318530718" upper="6.28318530718" velocity="3.14159" />
    <dynamics damping="60.0" friction="1.0" />
  </joint>
  <joint name="ur5e_joint_3" type="revolute">
    <parent link="ur5e_link_2" />
    <child link="ur5e_link_3" />
    <origin rpy="0 0 0" xyz="-0.425 0 0" />
    <axis xyz="0 0 1" />
    <limit effort="150.0" lower="-3.14159265359" upper="3.14159265359" velocity="3.14159" />
    <dynamics damping="35.0" friction="1.0" />
  </joint>
  <joint name="ur5e_joint_4" type="revolute">
    <parent link="ur5e_link_3" />
    <child link="ur5e_link_4" />
    <origin rpy="0 0 0" xyz="-0.3922 0 0.1333" />
    <axis xyz="0 0 1" />
    <limit effort="28.0" lower="-6.28318530718" upper="6.28318530718" velocity="3.14159" />
    <dynamics damping="20.0" friction="0.5" />
  </joint>
  <joint name="ur5e_joint_5" type="revolute">
    <parent link="ur5e_link_4" />
    <child link="ur5e_link_5" />
    <origin rpy="1.570796327 0 0" xyz="0 -0.0997 -2.0448811823e-11" />
    <axis xyz="0 0 1" />
    <limit effort="28.0" lower="-6.28318530718" upper="6.28318530718" velocity="3.14159" />
    <dynamics damping="20.0" friction="0.5" />
  </joint>
  <joint name="ur5e_joint_6" type="revolute">
    <parent link="ur5e_link_5" />
    <child link="ur5e_link_6" />
    <origin rpy="1.57079632659 3.14159265359 3.14159265359" xyz="0 0.0996 -2.04283014801e-11" />
    <axis xyz="0 0 1" />
    <limit effort="28.0" lower="-6.28318530718" upper="6.28318530718" velocity="3.14159" />
    <dynamics damping="15.0" friction="0.5" />
  </joint>
  <joint name="ur5e_base_fixed_joint" type="fixed">
    <origin rpy="0 0 3.14159265359" xyz="0 0 0" />
    <parent link="ur5e_base_link" />
    <child link="ur5e_base_fixed_link" />
  </joint>
  <joint name="ur5e_flange_joint" type="fixed">
    <parent link="ur5e_link_6" />
    <child link="ee_link" />
    <origin rpy="0 -1.57079632679 -1.57079632679" xyz="0 0 0" />
  </joint>
  <link name="wsg_mount_link">
    <inertial>
      <mass value="0.15" />
      <origin xyz="0 0 0" rpy="0 0 0" />
      <inertia ixx="0.00012" ixy="0" ixz="0" iyy="0.00012" iyz="0" izz="0.00012" />
    </inertial>
  </link>
  <link name="wsg_base_link">
    <visual>
      <origin xyz="0 0 0" rpy="0 0 0" />
      <geometry>
        <mesh filename="wsg50/meshes/WSG50_110.stl" />
      </geometry>
      <material name="wsg_gray" />
    </visual>
    <collision>
      <origin xyz="0 0 0.0363" rpy="0 0 0" />
      <geometry>
        <box size="0.146 0.05 0.073" />
      </geometry>
    </collision>
    <inertial>
      <mass value="1.2" />
      <origin xyz="0 0 0" rpy="0 0 0" />
      <inertia ixx="0.002" ixy="0" ixz="0" iyy="0.002" iyz="0" izz="0.002" />
    </inertial>
  </link>
  <link name="wsg_mount_visual_link">
    <visual>
      <origin xyz="0 0 0" rpy="0 0 0" />
      <geometry>
        <mesh filename="external_meshes/wsg50_mount.stl" />
      </geometry>
      <material name="mount_black" />
    </visual>
    <inertial>
      <mass value="0.001" />
      <origin xyz="0 0 0" rpy="0 0 0" />
      <inertia ixx="1e-09" ixy="0" ixz="0" iyy="1e-09" iyz="0" izz="1e-09" />
    </inertial>
  </link>
  <link name="wsg_left_slider_link">
    <visual>
      <origin xyz="0 0 0" rpy="0 0 0" />
      <geometry>
        <mesh filename="wsg50/meshes/GUIDE_WSG50_110.stl" scale="0.001 0.001 0.001" />
      </geometry>
      <material name="wsg_black" />
    </visual>
    <inertial>
      <mass value="0.1" />
      <origin xyz="0 0 0" rpy="0 0 0" />
      <inertia ixx="8e-05" ixy="0" ixz="0" iyy="8e-05" iyz="0" izz="8e-05" />
    </inertial>
  </link>
  <link name="wsg_right_slider_link">
    <visual>
      <origin xyz="0 0 0" rpy="0 0 3.141592654" />
      <geometry>
        <mesh filename="wsg50/meshes/GUIDE_WSG50_110.stl" scale="0.001 0.001 0.001" />
      </geometry>
      <material name="wsg_black" />
    </visual>
    <inertial>
      <mass value="0.1" />
      <origin xyz="0 0 0" rpy="0 0 0" />
      <inertia ixx="8e-05" ixy="0" ixz="0" iyy="8e-05" iyz="0" izz="8e-05" />
    </inertial>
  </link>
  <link name="soft_finger_left_link">
    <visual>
      <origin xyz="0 0 0" rpy="0 0 0" />
      <geometry>
        <mesh filename="external_meshes/soft_gripper_finger_left.stl" />
      </geometry>
      <material name="soft_finger_black" />
    </visual>
    <collision>
      <origin xyz="0.0165 -0.016 0.0129" rpy="0 0 0" />
      <geometry>
        <box size="0.033 0.032 0.026" />
      </geometry>
    </collision>
    <collision>
      <origin xyz="0.01575 -0.043 0.0129" rpy="0 0 0" />
      <geometry>
        <box size="0.0315 0.032 0.026" />
      </geometry>
    </collision>
    <collision>
      <origin xyz="0.012375 -0.069 0.0129" rpy="0 0 0" />
      <geometry>
        <box size="0.02475 0.032 0.026" />
      </geometry>
    </collision>
    <collision>
      <origin xyz="0.006 -0.093 0.0129" rpy="0 0 0" />
      <geometry>
        <box size="0.012 0.032 0.026" />
      </geometry>
    </collision>
    <collision>
      <origin xyz="0.0025 -0.113 0.0129" rpy="0 0 0" />
      <geometry>
        <box size="0.005 0.02 0.026" />
      </geometry>
    </collision>
    <inertial>
      <mass value="0.05" />
      <origin xyz="0 0 0" rpy="0 0 0" />
      <inertia ixx="4e-05" ixy="0" ixz="0" iyy="4e-05" iyz="0" izz="4e-05" />
    </inertial>
  </link>
  <link name="soft_finger_right_link">
    <visual>
      <origin xyz="0 0 0" rpy="0 0 0" />
      <geometry>
        <mesh filename="external_meshes/soft_gripper_finger_right.stl" />
      </geometry>
      <material name="soft_finger_black" />
    </visual>
    <collision>
      <origin xyz="-0.0165 -0.016 0.0129" rpy="0 0 0" />
      <geometry>
        <box size="0.033 0.032 0.026" />
      </geometry>
    </collision>
    <collision>
      <origin xyz="-0.01575 -0.043 0.0129" rpy="0 0 0" />
      <geometry>
        <box size="0.0315 0.032 0.026" />
      </geometry>
    </collision>
    <collision>
      <origin xyz="-0.012375 -0.069 0.0129" rpy="0 0 0" />
      <geometry>
        <box size="0.02475 0.032 0.026" />
      </geometry>
    </collision>
    <collision>
      <origin xyz="-0.006 -0.093 0.0129" rpy="0 0 0" />
      <geometry>
        <box size="0.012 0.032 0.026" />
      </geometry>
    </collision>
    <collision>
      <origin xyz="-0.0025 -0.113 0.0129" rpy="0 0 0" />
      <geometry>
        <box size="0.005 0.02 0.026" />
      </geometry>
    </collision>
    <inertial>
      <mass value="0.05" />
      <origin xyz="0 0 0" rpy="0 0 0" />
      <inertia ixx="4e-05" ixy="0" ixz="0" iyy="4e-05" iyz="0" izz="4e-05" />
    </inertial>
  </link>
  <link name="finger_holder_left_visual_link">
    <visual>
      <origin xyz="0 0 0" rpy="0 0 0" />
      <geometry>
        <mesh filename="external_meshes/finger_holder_left.obj" />
      </geometry>
      <material name="fin_mount_white" />
    </visual>
    <inertial>
      <mass value="0.001" />
      <origin xyz="0 0 0" rpy="0 0 0" />
      <inertia ixx="1e-09" ixy="0" ixz="0" iyy="1e-09" iyz="0" izz="1e-09" />
    </inertial>
  </link>
  <link name="finger_holder_right_visual_link">
    <visual>
      <origin xyz="0 0 0" rpy="0 0 0" />
      <geometry>
        <mesh filename="external_meshes/finger_holder_right.obj" />
      </geometry>
      <material name="fin_mount_white" />
    </visual>
    <inertial>
      <mass value="0.001" />
      <origin xyz="0 0 0" rpy="0 0 0" />
      <inertia ixx="1e-09" ixy="0" ixz="0" iyy="1e-09" iyz="0" izz="1e-09" />
    </inertial>
  </link>
  <link name="gemini_mount_link">
    <visual>
      <origin xyz="0 0 0" rpy="0 0 0" />
      <geometry>
        <mesh filename="external_meshes/gemini_mount.stl" />
      </geometry>
      <material name="mount_black" />
    </visual>
    <collision>
      <origin xyz="0.0058 0.0704 0.0055" rpy="0 0 0" />
      <geometry>
        <box size="0.053 0.075 0.021" />
      </geometry>
    </collision>
    <inertial>
      <mass value="0.04" />
      <origin xyz="0 0 0" rpy="0 0 0" />
      <inertia ixx="1e-05" ixy="0" ixz="0" iyy="1e-05" iyz="0" izz="1e-05" />
    </inertial>
  </link>
  <link name="gemini_305_link">
    <visual>
      <origin xyz="0 0 0" rpy="3.141592654 0 0" />
      <geometry>
        <mesh filename="gemini_305/meshes/gemini_305_rotated.obj" scale="0.001 0.001 0.001" />
      </geometry>
      <material name="gemini_305_gray" />
    </visual>
    <collision>
      <origin xyz="0 0 0" rpy="0 0 0" />
      <geometry>
        <box size="0.042 0.042 0.025" />
      </geometry>
    </collision>
    <inertial>
      <mass value="0.065" />
      <origin xyz="0 0 0" rpy="0 0 0" />
      <inertia ixx="1e-05" ixy="0" ixz="0" iyy="1e-05" iyz="0" izz="1e-05" />
    </inertial>
  </link>
  <link name="gemini_305_left_camera_frame">
    <inertial>
      <mass value="0.001" />
      <origin xyz="0 0 0" rpy="0 0 0" />
      <inertia ixx="1e-09" ixy="0" ixz="0" iyy="1e-09" iyz="0" izz="1e-09" />
    </inertial>
  </link>
  <link name="gemini_305_left_camera_optical_frame">
    <inertial>
      <mass value="0.001" />
      <origin xyz="0 0 0" rpy="0 0 0" />
      <inertia ixx="1e-09" ixy="0" ixz="0" iyy="1e-09" iyz="0" izz="1e-09" />
    </inertial>
  </link>
  <link name="gemini_305_right_camera_frame">
    <inertial>
      <mass value="0.001" />
      <origin xyz="0 0 0" rpy="0 0 0" />
      <inertia ixx="1e-09" ixy="0" ixz="0" iyy="1e-09" iyz="0" izz="1e-09" />
    </inertial>
  </link>
  <link name="gemini_305_right_camera_optical_frame">
    <inertial>
      <mass value="0.001" />
      <origin xyz="0 0 0" rpy="0 0 0" />
      <inertia ixx="1e-09" ixy="0" ixz="0" iyy="1e-09" iyz="0" izz="1e-09" />
    </inertial>
  </link>
  <link name="palm_frame">
    <inertial>
      <mass value="0.001" />
      <origin xyz="0 0 0" rpy="0 0 0" />
      <inertia ixx="1e-09" ixy="0" ixz="0" iyy="1e-09" iyz="0" izz="1e-09" />
    </inertial>
  </link>
  <link name="left_tip">
    <inertial>
      <mass value="0.001" />
      <origin xyz="0 0 0" rpy="0 0 0" />
      <inertia ixx="1e-09" ixy="0" ixz="0" iyy="1e-09" iyz="0" izz="1e-09" />
    </inertial>
  </link>
  <link name="right_tip">
    <inertial>
      <mass value="0.001" />
      <origin xyz="0 0 0" rpy="0 0 0" />
      <inertia ixx="1e-09" ixy="0" ixz="0" iyy="1e-09" iyz="0" izz="1e-09" />
    </inertial>
  </link>
  <joint name="wsg_mount_joint" type="fixed">
    <parent link="ee_link" />
    <child link="wsg_mount_link" />
    <origin xyz="0.01 0 0" rpy="-1.570796327 3.141592654 -1.570796327" />
  </joint>
  <joint name="wsg_base_mount_joint" type="fixed">
    <parent link="wsg_mount_link" />
    <child link="wsg_base_link" />
    <origin xyz="0 0 0" rpy="0 0 0" />
  </joint>
  <joint name="wsg_mount_visual_joint" type="fixed">
    <parent link="wsg_base_link" />
    <child link="wsg_mount_visual_link" />
    <origin xyz="0 0 0" rpy="0 0 0" />
  </joint>
  <joint name="wsg_left_finger_joint" type="prismatic">
    <parent link="wsg_base_link" />
    <child link="wsg_left_slider_link" />
    <origin xyz="0 0 0" rpy="0 0 0" />
    <axis xyz="1 0 0" />
    <limit lower="-0.055" upper="-0.0027" effort="100" velocity="0.2" />
    <dynamics damping="10" friction="1" />
  </joint>
  <joint name="wsg_right_finger_joint" type="prismatic">
    <parent link="wsg_base_link" />
    <child link="wsg_right_slider_link" />
    <origin xyz="0 0 0" rpy="0 0 0" />
    <axis xyz="1 0 0" />
    <limit lower="0.0027" upper="0.055" effort="100" velocity="0.2" />
    <dynamics damping="10" friction="1" />
  </joint>
  <joint name="soft_finger_left_joint" type="fixed">
    <parent link="wsg_left_slider_link" />
    <child link="soft_finger_left_link" />
    <origin xyz="0 0.013 0.098" rpy="-1.570796327 0 -3.141592654" />
  </joint>
  <joint name="soft_finger_right_joint" type="fixed">
    <parent link="wsg_right_slider_link" />
    <child link="soft_finger_right_link" />
    <origin xyz="0 0.013 0.098" rpy="-1.570796327 0 -3.141592654" />
  </joint>
  <joint name="finger_holder_left_visual_joint" type="fixed">
    <parent link="soft_finger_left_link" />
    <child link="finger_holder_left_visual_link" />
    <origin xyz="-0.001 0.101 0.013" rpy="1.570796327 0 0" />
  </joint>
  <joint name="finger_holder_right_visual_joint" type="fixed">
    <parent link="soft_finger_right_link" />
    <child link="finger_holder_right_visual_link" />
    <origin xyz="0.001 0.1 0.013" rpy="1.570796327 0 0" />
  </joint>
  <joint name="left_tip_joint" type="fixed">
    <parent link="soft_finger_left_link" />
    <child link="left_tip" />
    <origin xyz="0.0005 -0.1085 0.0129" rpy="3.141592654 3.141592654 3.141592654" />
  </joint>
  <joint name="right_tip_joint" type="fixed">
    <parent link="soft_finger_right_link" />
    <child link="right_tip" />
    <origin xyz="-0.0005 -0.1085 0.0129" rpy="0 0 3.141592654" />
  </joint>
  <joint name="palm_frame_joint" type="fixed">
    <parent link="wsg_base_link" />
    <child link="palm_frame" />
    <origin xyz="0 0 0.146" rpy="0 0 0" />
  </joint>
  <joint name="gemini_mount_joint" type="fixed">
    <parent link="wsg_base_link" />
    <child link="gemini_mount_link" />
    <origin xyz="0 0.0025 0.0235" rpy="3.141592654 0 3.141592654" />
  </joint>
  <joint name="gemini_305_mount_joint" type="fixed">
    <parent link="gemini_mount_link" />
    <child link="gemini_305_link" />
    <origin xyz="0 0.085 -0.0085" rpy="-2.879793266 0 3.141592654" />
  </joint>
  <joint name="gemini_305_left_camera_joint" type="fixed">
    <parent link="gemini_305_link" />
    <child link="gemini_305_left_camera_frame" />
    <origin xyz="0.009 0 0.0126" rpy="0 0 0" />
  </joint>
  <joint name="gemini_305_left_optical_joint" type="fixed">
    <parent link="gemini_305_left_camera_frame" />
    <child link="gemini_305_left_camera_optical_frame" />
    <origin xyz="0 0 0" rpy="0 0 3.141592654" />
  </joint>
  <joint name="gemini_305_right_camera_joint" type="fixed">
    <parent link="gemini_305_link" />
    <child link="gemini_305_right_camera_frame" />
    <origin xyz="-0.009 0 0.0126" rpy="0 0 0" />
  </joint>
  <joint name="gemini_305_right_optical_joint" type="fixed">
    <parent link="gemini_305_right_camera_frame" />
    <child link="gemini_305_right_camera_optical_frame" />
    <origin xyz="0 0 0" rpy="0 0 3.141592654" />
  </joint>
</robot>